[2023-10-11 14:11:17,716] {taskinstance.py:1159} INFO - Dependencies all met for <TaskInstance: 1_init_once_seed_data.load_seed_data_once manual__2023-10-11T14:11:17.160495+00:00 [queued]>
[2023-10-11 14:11:17,729] {taskinstance.py:1159} INFO - Dependencies all met for <TaskInstance: 1_init_once_seed_data.load_seed_data_once manual__2023-10-11T14:11:17.160495+00:00 [queued]>
[2023-10-11 14:11:17,730] {taskinstance.py:1356} INFO - 
--------------------------------------------------------------------------------
[2023-10-11 14:11:17,731] {taskinstance.py:1357} INFO - Starting attempt 1 of 1
[2023-10-11 14:11:17,732] {taskinstance.py:1358} INFO - 
--------------------------------------------------------------------------------
[2023-10-11 14:11:17,746] {taskinstance.py:1377} INFO - Executing <Task(BashOperator): load_seed_data_once> on 2023-10-11 14:11:17.160495+00:00
[2023-10-11 14:11:17,751] {standard_task_runner.py:52} INFO - Started process 5261 to run task
[2023-10-11 14:11:17,754] {standard_task_runner.py:79} INFO - Running: ['***', 'tasks', 'run', '1_init_once_seed_data', 'load_seed_data_once', 'manual__2023-10-11T14:11:17.160495+00:00', '--job-id', '45', '--raw', '--subdir', 'DAGS_FOLDER/init.py', '--cfg-path', '/tmp/tmpwdsek52g', '--error-file', '/tmp/tmpxhlihs01']
[2023-10-11 14:11:17,755] {standard_task_runner.py:80} INFO - Job 45: Subtask load_seed_data_once
[2023-10-11 14:11:17,810] {task_command.py:369} INFO - Running <TaskInstance: 1_init_once_seed_data.load_seed_data_once manual__2023-10-11T14:11:17.160495+00:00 [running]> on host c2e542998ec2
[2023-10-11 14:11:17,920] {taskinstance.py:1571} INFO - Exporting the following env vars:
AIRFLOW_CTX_DAG_OWNER=***
AIRFLOW_CTX_DAG_ID=1_init_once_seed_data
AIRFLOW_CTX_TASK_ID=load_seed_data_once
AIRFLOW_CTX_EXECUTION_DATE=2023-10-11T14:11:17.160495+00:00
AIRFLOW_CTX_TRY_NUMBER=1
AIRFLOW_CTX_DAG_RUN_ID=manual__2023-10-11T14:11:17.160495+00:00
[2023-10-11 14:11:17,922] {subprocess.py:62} INFO - Tmp dir root location: 
 /tmp
[2023-10-11 14:11:17,923] {subprocess.py:74} INFO - Running command: ['bash', '-c', 'cd /dbt_snowflake/dbt && ls']
[2023-10-11 14:11:17,932] {subprocess.py:85} INFO - Output:
[2023-10-11 14:11:17,935] {subprocess.py:92} INFO - bash: line 1: cd: /dbt_snowflake/dbt: No such file or directory
[2023-10-11 14:11:17,937] {subprocess.py:96} INFO - Command exited with return code 1
[2023-10-11 14:11:17,952] {taskinstance.py:1889} ERROR - Task failed with exception
Traceback (most recent call last):
  File "/home/airflow/.local/lib/python3.7/site-packages/airflow/operators/bash.py", line 195, in execute
    f'Bash command failed. The command returned a non-zero exit code {result.exit_code}.'
airflow.exceptions.AirflowException: Bash command failed. The command returned a non-zero exit code 1.
[2023-10-11 14:11:17,956] {taskinstance.py:1400} INFO - Marking task as FAILED. dag_id=1_init_once_seed_data, task_id=load_seed_data_once, execution_date=20231011T141117, start_date=20231011T141117, end_date=20231011T141117
[2023-10-11 14:11:17,968] {standard_task_runner.py:97} ERROR - Failed to execute job 45 for task load_seed_data_once (Bash command failed. The command returned a non-zero exit code 1.; 5261)
[2023-10-11 14:11:18,009] {local_task_job.py:156} INFO - Task exited with return code 1
[2023-10-11 14:11:18,065] {local_task_job.py:273} INFO - 0 downstream tasks scheduled from follow-on schedule check
